Workbook

Sheet Sheet1
B1: date | C1: menuName | D1: memberName | E1: price | F1: note | G1: status | H1: supplier | I1: groupID | J1: menuID | K1: memberID
B2: 45261 | C2: 金湯酸菜魚套餐 | D2: Shi, Zhao-Yong | E2: 34 | I2: lunch_hp | J2: =VLOOKUP(C2,MenuID!B:C,2,) -> f070138d6a3232cc004cac101d617e55 | K2: =VLOOKUP(D2,MemberID!A:B,2,) -> 117e1a7d6a32375b0032e4e503b8a95d
B3: 45261 | C3: 秘制牛肉 | D3: Wan, Jia-Nian | E3: 0 | I3: lunch_hp | J3: =VLOOKUP(C3,MenuID!B:C,2,) -> #N/A | K3: =VLOOKUP(D3,MemberID!A:B,2,) -> 117e1a7d6a32375b0032e4e75d4f00aa
B4: 45261 | C4: 梅菜扣肉套餐 | D4: Wang, Cheng-Yu | E4: 30 | I4: lunch_hp | J4: =VLOOKUP(C4,MenuID!B:C,2,) -> f070138d6a3232cc004cac0d6f87f4e0 | K4: =VLOOKUP(D4,MemberID!A:B,2,) -> #N/A
B5: 45261 | C5: 梅菜扣肉套餐 | D5: Xiong, Wenjun | E5: 30 | I5: lunch_hp | J5: =VLOOKUP(C5,MenuID!B:C,2,) -> f070138d6a3232cc004cac0d6f87f4e0 | K5: =VLOOKUP(D5,MemberID!A:B,2,) -> 117e1a7d6a32375b0032e4e94c678d6e
B6: 45261 | C6: 梅菜扣肉套餐 | D6: Zeng, Daniel | E6: 30 | I6: lunch_hp | J6: =VLOOKUP(C6,MenuID!B:C,2,) -> f070138d6a3232cc004cac0d6f87f4e0 | K6: =VLOOKUP(D6,MemberID!A:B,2,) -> 117e1a7d6a32375b0032e4ec164af75f
B7: 45261 | C7: 咖喱牛肉饭 | D7: Zhang, Hai-Tao | E7: 30 | I7: lunch_hp | J7: =VLOOKUP(C7,MenuID!B:C,2,) -> 117e1a7d6a3232cc0032ba8a3c10c6b1 | K7: =VLOOKUP(D7,MemberID!A:B,2,) -> 117e1a7d6a32375b0032e4ed77ddbf3c
B8: 45261 | C8: 咖喱牛肉饭 | D8: Zhang, Xin-Guo | E8: 30 | I8: lunch_hp | J8: =VLOOKUP(C8,MenuID!B:C,2,) -> 117e1a7d6a3232cc0032ba8a3c10c6b1 | K8: =VLOOKUP(D8,MemberID!A:B,2,) -> 117e1a7d6a32375b0032e4ee31a66c55
B9: 45261 | C9: 雞腿飯 | D9: Zhou, HongLiang | E9: 27 | I9: lunch_hp | J9: =VLOOKUP(C9,MenuID!B:C,2,) -> 117e1a7d6a3232cc0032ba841bacdc09 | K9: =VLOOKUP(D9,MemberID!A:B,2,) -> 117e1a7d6a32375b0032e4ef27297d42
B10: 45261 | C10: 金湯酸菜魚套餐 | D10: Zhou Yong | E10: 34 | I10: lunch_hp | J10: =VLOOKUP(C10,MenuID!B:C,2,) -> f070138d6a3232cc004cac101d617e55 | K10: =VLOOKUP(D10,MemberID!A:B,2,) -> 117e1a7d6a32375b0032e4f07f23b606
B11: 45261 | C11: 雞腿飯 | D11: Ge, Neal | E11: 27 | I11: lunch_hp | J11: =VLOOKUP(C11,MenuID!B:C,2,) -> 117e1a7d6a3232cc0032ba841bacdc09 | K11: =VLOOKUP(D11,MemberID!A:B,2,) -> 117e1a7d6a32375b0032e4df575c9dff
B12: 45261 | C12: 金湯酸菜魚套餐 | D12: Mao, Kun | E12: 34 | I12: lunch_hp | J12: =VLOOKUP(C12,MenuID!B:C,2,) -> f070138d6a3232cc004cac101d617e55 | K12: =VLOOKUP(D12,MemberID!A:B,2,) -> 117e1a7d6a32375b0032e4e33eae3cfc
B13: 45261 | C13: 金湯酸菜魚套餐 | D13: Alex | E13: 34 | I13: lunch_hp | J13: =VLOOKUP(C13,MenuID!B:C,2,) -> f070138d6a3232cc004cac101d617e55 | K13: =VLOOKUP(D13,MemberID!A:B,2,) -> 117e1a7d6a32375b0032e4f1728479df
... B602: 45436 | C602: 金湯酸菜魚套餐 | D602: Zhou Yong | E602: 34 | I602: lunch_hp | J602: =VLOOKUP(C602,MenuID!B:C,2,) -> f070138d6a3232cc004cac101d617e55 | K602: =VLOOKUP(D602,MemberID!A:B,2,) -> 117e1a7d6a32375b0032e4f07f23b606
B603: 45436 | C603: 秘制牛肉 | D603: Xiong, Wenjun | I603: lunch_hp | J603: =VLOOKUP(C603,MenuID!B:C,2,) -> #N/A | K603: =VLOOKUP(D603,MemberID!A:B,2,) -> 117e1a7d6a32375b0032e4e94c678d6e
B604: 45436 | C604: 金湯酸菜魚套餐 | D604: Su, Jun | E604: 34 | I604: lunch_hp | J604: =VLOOKUP(C604,MenuID!B:C,2,) -> f070138d6a3232cc004cac101d617e55 | K604: =VLOOKUP(D604,MemberID!A:B,2,) -> 117e1a7d6a32375b0032e4e6270171de
B605: 45439 | C605: 金湯酸菜魚套餐 | D605: Zhou Yong | E605: 34 | I605: lunch_hp | J605: =VLOOKUP(C605,MenuID!B:C,2,) -> f070138d6a3232cc004cac101d617e55 | K605: =VLOOKUP(D605,MemberID!A:B,2,) -> 117e1a7d6a32375b0032e4f07f23b606
B606: 45439 | C606: 雞腿飯 | D606: Ge, Neal | E606: 27 | I606: lunch_hp | J606: =VLOOKUP(C606,MenuID!B:C,2,) -> 117e1a7d6a3232cc0032ba841bacdc09 | K606: =VLOOKUP(D606,MemberID!A:B,2,) -> 117e1a7d6a32375b0032e4df575c9dff
B607: 45439 | C607: 雞腿飯 | D607: Wang, Cheng-Yu | E607: 27 | I607: lunch_hp | J607: =VLOOKUP(C607,MenuID!B:C,2,) -> 117e1a7d6a3232cc0032ba841bacdc09 | K607: =VLOOKUP(D607,MemberID!A:B,2,) -> #N/A
B608: 45439 | C608: 金湯酸菜魚套餐 | D608: Xu, Jian | E608: 34 | I608: lunch_hp | J608: =VLOOKUP(C608,MenuID!B:C,2,) -> f070138d6a3232cc004cac101d617e55 | K608: =VLOOKUP(D608,MemberID!A:B,2,) -> 117e1a7d6a32375b0032e4ea6656f4f1
B609: 45439 | C609: 梅菜扣肉套餐 | D609: Xiong, Wenjun | E609: 30 | I609: lunch_hp | J609: =VLOOKUP(C609,MenuID!B:C,2,) -> f070138d6a3232cc004cac0d6f87f4e0 | K609: =VLOOKUP(D609,MemberID!A:B,2,) -> 117e1a7d6a32375b0032e4e94c678d6e
B610: 45439 | C610: 肉末茄子套餐 | D610: Zeng, Daniel | E610: 24 | I610: lunch_hp | J610: =VLOOKUP(C610,MenuID!B:C,2,) -> f070138d6a3232cc004cac0f417e3be6 | K610: =VLOOKUP(D610,MemberID!A:B,2,) -> 117e1a7d6a32375b0032e4ec164af75f
B611: 45439 | C611: 金湯酸菜魚套餐 | D611: Wan, Jia-Nian | E611: 34 | I611: lunch_hp | J611: =VLOOKUP(C611,MenuID!B:C,2,) -> f070138d6a3232cc004cac101d617e55 | K611: =VLOOKUP(D611,MemberID!A:B,2,) -> 117e1a7d6a32375b0032e4e75d4f00aa
B612: 45439 | C612: 金湯酸菜魚套餐 | D612: Zhang, Xin-Guo | E612: 34 | I612: lunch_hp | J612: =VLOOKUP(C612,MenuID!B:C,2,) -> f070138d6a3232cc004cac101d617e55 | K612: =VLOOKUP(D612,MemberID!A:B,2,) -> 117e1a7d6a32375b0032e4ee31a66c55
B613: 45439 | C613: 浓香猪脚煲套餐 | D613: Zhang, Hai-Tao | E613: 37 | I613: lunch_hp | J613: =VLOOKUP(C613,MenuID!B:C,2,) -> f070138d6a3232cc004cac114f946662 | K613: =VLOOKUP(D613,MemberID!A:B,2,) -> 117e1a7d6a32375b0032e4ed77ddbf3c
B614: 45439 | C614: 浓香猪脚煲套餐 | D614: Zhang, Hai-Tao | E614: 37 | I614: lunch_hp | J614: =VLOOKUP(C614,MenuID!B:C,2,) -> f070138d6a3232cc004cac114f946662 | K614: =VLOOKUP(D614,MemberID!A:B,2,) -> 117e1a7d6a32375b0032e4ed77ddbf3c
B615: 45439 | C615: 雞腿飯 | D615: Mao, Kun | E615: 27 | I615: lunch_hp | J615: =VLOOKUP(C615,MenuID!B:C,2,) -> 117e1a7d6a3232cc0032ba841bacdc09 | K615: =VLOOKUP(D615,MemberID!A:B,2,) -> 117e1a7d6a32375b0032e4e33eae3cfc
... B621: 45440 | C621: 魚香肉絲 | D621: Hu, Yao-Qing | E621: 23 | I621: lunch_hp | J621: =VLOOKUP(C621,MenuID!B:C,2,) -> 117e1a7d6a3232cc0032ba8c6d2cb4d3 | K621: =VLOOKUP(D621,MemberID!A:B,2,) -> 117e1a7d6a32375b0032e4e109cccaf3
B622: 45440 | C622: 秘制牛肉 | D622: Dou, Cindy | I622: lunch_hp | J622: =VLOOKUP(C622,MenuID!B:C,2,) -> #N/A | K622: =VLOOKUP(D622,MemberID!A:B,2,) -> 117e1a7d6a32375b0032e4de4195c0ce
B623: 45440 | C623: 金湯酸菜魚套餐 | D623: Shi, Zhao-Yong | E623: 34 | I623: lunch_hp | J623: =VLOOKUP(C623,MenuID!B:C,2,) -> f070138d6a3232cc004cac101d617e55 | K623: =VLOOKUP(D623,MemberID!A:B,2,) -> 117e1a7d6a32375b0032e4e503b8a95d
B624: 45440 | C624: 肉末茄子套餐 | D624: Shi, Zhao-Yong | E624: 24 | I624: lunch_hp | J624: =VLOOKUP(C624,MenuID!B:C,2,) -> f070138d6a3232cc004cac0f417e3be6 | K624: =VLOOKUP(D624,MemberID!A:B,2,) -> 117e1a7d6a32375b0032e4e503b8a95d
B625: 45440 | C625: 盐烤青花鱼便当 | D625: Qiao, Xiu-Jun | E625: 48 | I625: lunch_hp | J625: =VLOOKUP(C625,MenuID!B:C,2,) -> f070138d6a3232cc004cac151e8fe14b | K625: =VLOOKUP(D625,MemberID!A:B,2,) -> 117e1a7d6a32375b0032e4e405c4b42b
B626: 45440 | C626: 盐烤青花鱼便当 | D626: Zhang, Xin-Guo | E626: 48 | I626: lunch_hp | J626: =VLOOKUP(C626,MenuID!B:C,2,) -> f070138d6a3232cc004cac151e8fe14b | K626: =VLOOKUP(D626,MemberID!A:B,2,) -> 117e1a7d6a32375b0032e4ee31a66c55
B627: 45440 | C627: 盐烤青花鱼便当 | D627: Anna | E627: 48 | I627: lunch_hp | J627: =VLOOKUP(C627,MenuID!B:C,2,) -> f070138d6a3232cc004cac151e8fe14b | K627: =VLOOKUP(D627,MemberID!A:B,2,) -> f070138d6a32375b004ce0e012ab9b33
B628: 45440 | C628: 浓香猪脚煲套餐 | D628: Zhang, Hai-Tao | E628: 37 | I628: lunch_hp | J628: =VLOOKUP(C628,MenuID!B:C,2,) -> f070138d6a3232cc004cac114f946662 | K628: =VLOOKUP(D628,MemberID!A:B,2,) -> 117e1a7d6a32375b0032e4ed77ddbf3c
B629: 45440 | C629: 浓香猪脚煲套餐 | D629: Zhang, Hai-Tao | E629: 37 | I629: lunch_hp | J629: =VLOOKUP(C629,MenuID!B:C,2,) -> f070138d6a3232cc004cac114f946662 | K629: =VLOOKUP(D629,MemberID!A:B,2,) -> 117e1a7d6a32375b0032e4ed77ddbf3c
B630: 45440 | C630: 浓香猪脚煲套餐 | D630: Su, Jun | E630: 37 | I630: lunch_hp | J630: =VLOOKUP(C630,MenuID!B:C,2,) -> f070138d6a3232cc004cac114f946662 | K630: =VLOOKUP(D630,MemberID!A:B,2,) -> 117e1a7d6a32375b0032e4e6270171de
B631: 45440 | C631: 浓香猪脚煲套餐 | D631: Xiong, Wenjun | E631: 37 | I631: lunch_hp | J631: =VLOOKUP(C631,MenuID!B:C,2,) -> f070138d6a3232cc004cac114f946662 | K631: =VLOOKUP(D631,MemberID!A:B,2,) -> 117e1a7d6a32375b0032e4e94c678d6e
B632: 45440 | C632: 浓香猪脚煲套餐 | D632: Wang, Cheng-Yu | E632: 37 | I632: lunch_hp | J632: =VLOOKUP(C632,MenuID!B:C,2,) -> f070138d6a3232cc004cac114f946662 | K632: =VLOOKUP(D632,MemberID!A:B,2,) -> #N/A
B633: 45440 | C633: 雞腿飯 | D633: Ge, Neal | E633: 27 | I633: lunch_hp | J633: =VLOOKUP(C633,MenuID!B:C,2,) -> 117e1a7d6a3232cc0032ba841bacdc09 | K633: =VLOOKUP(D633,MemberID!A:B,2,) -> 117e1a7d6a32375b0032e4df575c9dff
...

Sheet MenuID
B1: name | C1: _id
B2: 雞腿飯 | C2: 117e1a7d6a3232cc0032ba841bacdc09
B3: 香腸飯 | C3: 117e1a7d6a3232cc0032ba856e45e306
B4: 香酥排骨飯 | C4: 117e1a7d6a3232cc0032ba8633046662
B5: 紅燒排骨 | C5: 117e1a7d6a3232cc0032ba877fba8727
B6: 香辣牛肉 | C6: 117e1a7d6a3232cc0032ba880059b9ea
B7: 酸甜糖醋里脊饭 | C7: 117e1a7d6a3232cc0032ba892841cc16
B8: 咖喱牛肉饭 | C8: 117e1a7d6a3232cc0032ba8a3c10c6b1
B9: 梅菜扣肉饭 | C9: 117e1a7d6a3232cc0032ba8b49daedbb
B10: 魚香肉絲 | C10: 117e1a7d6a3232cc0032ba8c6d2cb4d3
B11: 全素 | C11: 117e1a7d6a3232cc0032ba8d0f25aa48
B12: 肉沫茄子便当 | C12: 117e1a7d6a3232cc0032ba8e4ea044aa
... B47: 豪華三拼牛肉雞胸蝦仁烤蔬套餐 | C47: 5caf1a7c6a3232cc017db32c4099e5ae

Sheet MemberID
A1: name | B1: _id
A2: Dou, Cindy | B2: 117e1a7d6a32375b0032e4de4195c0ce
A3: Ge, Neal | B3: 117e1a7d6a32375b0032e4df575c9dff
A4: Guo, Xiao-Jian | B4: 117e1a7d6a32375b0032e4e04e8766de
A5: Hu, Yao-Qing | B5: 117e1a7d6a32375b0032e4e109cccaf3
A6: Liu, Jianping | B6: 117e1a7d6a32375b0032e4e22355c574
A7: Mao, Kun | B7: 117e1a7d6a32375b0032e4e33eae3cfc
A8: Qiao, Xiu-Jun | B8: 117e1a7d6a32375b0032e4e405c4b42b
A9: Shi, Zhao-Yong | B9: 117e1a7d6a32375b0032e4e503b8a95d
A10: Su, Jun | B10: 117e1a7d6a32375b0032e4e6270171de
A11: Wan, Jia-Nian | B11: 117e1a7d6a32375b0032e4e75d4f00aa
A12: Xiong, Wenjun | B12: 117e1a7d6a32375b0032e4e94c678d6e
... A45: 王成余 | B45: 5caf1a7c6a32b95f01a95396443f7542
B46: f070138d6a334829005b88b54385c115
